Workbook

Sheet 首页
A1: 4.0.22公民教育
A2: 4.0.22版审核 | B2: =_xlfn.DISPIMG("ID_8A95646438884BE8BA5ED17D3AFF9A8C",1) -> =DISPIMG("ID_8A95646438884BE8BA5ED17D3AFF9A8C",1)
A3: Stellaris 维基
A4: https://stellaris.paradoxwikis.com/Stellaris_Wiki
A5: 一.本文档最后更新于2025.08.27，适配版本号4.0.22，天灾宝典编辑群684118724，使用WPS Office软件编写（不同软件可能无法正常显示相关代码）
A6: 二.本文档收录内容：控制台中文对照，扩展代码，起源，国策，传统，飞升，思潮，物种特质，领袖特质，星球类型及建筑区划，科技，巨构，异常，部分起始事件链，考古遗址，星界裂隙，标本，遗珍，行星矿藏，修正（包含国家，行星，舰队，人口），特殊星系生成，全局舰船设计，舰船组件，成就，环境物体，组合代码
A7: 三.本文档基于【群星3.10.4天灾宝典】所做的更新与拓展，对其已失效或内容文本与当前版本不符合的部分进行了修改，对新增加条目进行了更新，在此基础上新增了更多条目。更多代码来源于原来的天灾宝典，群星英文wiki，以及猪圈的一些大神提供。
A8: 四.功能介绍及使用方法
A9: 1.控制台：在不开启铁人模式的情况下，点击“~”键进入控制台界面，显示界面的对照翻译，部分名称为？？？，是中文无法转变，但跟翻译表内位置一样。
A10: 2.扩展代码：多数扩展代码都标注了使用方法（例如选中xxx），未标注的为不需要选中任何物体，本项目栏包含：玩家常用代码，联邦，星海共同体，星球决议，陆军，法令，领袖，部分物种特质解锁，建筑解锁及加成，先驱者，部分数量计数器，高级政体切换，噬天巨兽行动，外交，资源添加，太空风暴生成，太空生物相关，舰船模型（原图形文化），更换国家背景，机械爹，L-星门事件，虚境契约，天灾事件计数器。
A11: 3.起源：包含游戏全部起源，直接输入即可。
A12: 4.国策：包含游戏全部国策，直接输入即可。
A13: 5.传统：包含游戏全部传统，直接输入即可。
A14: 6.飞升：包含游戏全部飞升，直接输入即可。
... A34: 26.舰船组件：用于改派。

Sheet 控制台
B1: ▼ Debug View | M1: × | R1: × | V1: ▼ Debug View | AL1: ×
B2: Debug Controls | O2: Debug Views | V2: Debug Controls | AI2: Debug Views
B3: ▼ Quick Access | V3: ▼ 经常使用
B4: Last daily tick: 0 ms | I4: Last 30 daily ticks avg: 0 ms | V4: Last daily tick: 0 ms | AC4: Last 30 daily ticks avg: 0 ms
B6: █ Debug Tooltips | F6: █ Instant Move | J6: █ AI | V6: █ 查看隐藏信息 | Z6: █ 船只瞬移 | AD6: █ 电脑ai开关
B7: █ Guibounds | F7: █ Instant Survey | J7: █ Human AI | V7: █ 显示UI元素信息 | Z7: █ 瞬间调查 | AD7: █ 将玩家帝国托管给电脑ai
B8: █ No Agreement CD | F8: █ Instant Research | J8: █ No Full Takeover | V8: █ 无_协议CD | Z8: █ 瞬间完成研究 | AD8: █ 接管玩家帝国后切换AI被动行为
B9: █ No GalCom CD | F9: █ Instant Build | V9: █ 无_星海共同体议案CD | Z9: █ 立刻完成建造
B10: █ No Federation CD | F10: █ Instant Anomaly | V10: █ 无_联邦法律切换CD | Z10: █ 瞬间完成异常现象调查
F11: █ Instant Colony | Z11: █ 瞬间完成殖民
B20: ▼ Resources | V20: ▼ 资源类
B22: ▼ Strategic Resources | V22: ▼ 基础资源
I23: Energy Credits | AC23: 能量币
I24: Minerals | AC24: 矿物
I25: Food | AC25: 食物
I26: Consumer | AC26: 消费品
I27: Alloys | AC27: 合金
I28: Influence | AC28: 影响力
I29: Unity | AC29: 凝聚力
B30: ▼ Special Resources | V30: ▼ 稀有资源
I31: trade | AC31: 贸易
I32: Volatile Motes | AC32: 易爆微粒
I33: Exotic Gases | AC33: 异星天然气
I34: Rare Crystals | AC34: 稀有水晶
I35: Living Metal | AC35: 活体金属
I36: Zro | AC36: 泽珞
I37: Dark Matter | AC37: 暗物质
I38: Minor Artifacts | AC38: 稀有文物
I39: Astral Threads | AC39: 星界丝缕
I40: Physics Research | AC40: 物理学研究
I41: Society Research | AC41: 社会学研究
I42: Engineering Research | AC42: 工程学研究
... I47: Feral Insight | AC47: 野性洞见（巨兽之怒）
B51: ▼ Map | V51: ▼ 地图
B54: █ instant_move | V54: █ 瞬间移动
B55: █ instant_suryey | V55: █ 瞬间调查
B56: █ instant_recearch | V56: █ 瞬间研究
B57: █ instant_anomaly_research | V57: █ 瞬间完成异常研究
B59: ▼ Time | V59: ▼ 时间（这一项尽量不要用，有BUG）
J60: ticks_per_turn | AD60: 加速时间的进程
...

Sheet 扩展代码
A1: 4.0.22扩展代码（2025.08.21）
A2: 注：效果或备注栏写明了使用方法，注意仔细阅读；在选择栏双击即可跳转相关代码；部分代码点击下拉栏即可生成对应代码。 “其他”栏目前包括：资源添加，太空风暴生成，太空生物相关，舰船模型（原图形文化），更换国家背景，机械爹，L-星门事件，虚境契约，天灾事件计数器。
A3: 选择栏 | B3: {=HYPERLINK("#"&ADDRESS(MATCH("玩家",A:A,0),COLUMN(A:A)),"玩家")} -> 玩家 | C3: {=HYPERLINK("#"&ADDRESS(MATCH("联邦",A:A,0),COLUMN(A:A)),"联邦")} -> 联邦 | D3: {=HYPERLINK("#"&ADDRESS(MATCH("星海共同体",A:A,0),COLUMN(A:A)),"星海共同体")} -> 星海共同体 | E3: {=HYPERLINK("#"&ADDRESS(MATCH("星球决议",A:A,0),COLUMN(A:A)),"星球决议")} -> 星球决议 | F3: {=HYPERLINK("#"&ADDRESS(MATCH("陆军",A:A,0),COLUMN(A:A)),"陆军")} -> 陆军
B4: {=HYPERLINK("#"&ADDRESS(MATCH("法令",A:A,0),COLUMN(A:A)),"法令")} -> 法令 | C4: {=HYPERLINK("#"&ADDRESS(MATCH("领袖",A:A,0),COLUMN(A:A)),"领袖")} -> 领袖 | D4: {=HYPERLINK("#"&ADDRESS(MATCH("物种特质",A:A,0),COLUMN(A:A)),"物种特质")} -> 物种特质 | E4: {=HYPERLINK("#"&ADDRESS(MATCH("建筑",A:A,0),COLUMN(A:A)),"建筑")} -> 建筑 | F4: {=HYPERLINK("#"&ADDRESS(MATCH("先驱者",A:A,0),COLUMN(A:A)),"先驱者")} -> 先驱者
B5: {=HYPERLINK("#"&ADDRESS(MATCH("数量",A:A,0),COLUMN(A:A)),"数量")} -> 数量 | C5: {=HYPERLINK("#"&ADDRESS(MATCH("高级政体",A:A,0),COLUMN(A:A)),"高级政体")} -> 高级政体 | D5: {=HYPERLINK("#"&ADDRESS(MATCH("噬天巨兽行动",A:A,0),COLUMN(A:A)),"噬天巨兽行动")} -> 噬天巨兽行动 | E5: {=HYPERLINK("#"&ADDRESS(MATCH("顶级掠食者特质",A:A,0),COLUMN(A:A)),"顶级掠食者特质")} -> 顶级掠食者特质 | F5: {=HYPERLINK("#"&ADDRESS(MATCH("外交",A:A,0),COLUMN(A:A)),"外交")} -> 外交
B6: {=HYPERLINK("#"&ADDRESS(MATCH("其他",A:A,0),COLUMN(A:A)),"其他")} -> 其他 | F6: 附表
A7: 类别 | B7: 效果 | C7: 代码 | F7: 备注
A8: 玩家 | B8: 选中物体归玩家所有 | C8: own
B9: 更换游玩0号帝国 | C9: play 0
B10: ai同意所有条款 | C10: yesmen
B11: ai否决所有条款 | C11: nomen
B12: 对选中星球添加物种0号100人 | C12: add_pops 0 100
B13: 杀死当前国家 | C13: kill_country
B14: 立刻开始选举国家领袖 | C14: election
B15: 舰船无敌 | C15: invincible
B16: 添加舰船设计名称1的舰船1个 | C16: add_ship 1
B17: 对选中舰船造成10000伤害 | C17: damage 10000
B18: 对选中行星增加x破坏度 | C18: effect add_planet_devastation = x | F18: x为负数就是减少破坏度
B19: 对选中局势增加x进度 | C19: effect add_situation_progress = x | F19: x为负数就是减少局势进度
B20: 使国家ID1对国家ID0增加100好感 | C20: add_opinion 1 0 100
B21: 使国家ID1对国家ID0增加100信任度 | C21: add_trust 1 0 100
B22: 对国家ID1增加1000渗透度 | C22: add_spynetwork_value 1 1000
B23: 对国家ID1增加100情报 | C23: add_intel 1 100
B24: 对国家ID1增加50忠诚度 | C24: add_loyalty 1 50
B25: 向1号特化附庸国家增加1000经验 | C25: add_subject_xp 1 1000
B26: ai侵略性最大化 | C26: berserk_ai
B27: 完成环境改造 | C27: finish_terraform
B28: 将1号帝国整合进玩家帝国 | C28: force_integrate 1
B29: 改革物种权利 | C29: free_policies
B30: 改革政府 | C30: free_government
B31: 重置政策冷却 | C31: effect reset_policy_cooldowns = yes
... B37: 使终末危机的倍率乘10倍 | C37: effect multiply_crisis_strength = 1.3333
B38: 设置已完成的星界裂隙数量为5 | C38: effect set_completed_rifts 5 | F38: （已失效）
B39: 解锁内阁席位1 | C39: effect unlock_council_slots = 1
B40: 推进当前星球考古阶段 | C40: finish_arc_stage
B41: 删除这个考古遗址 | C41: effect destroy_archaeological_site = this
B42: 推进当前星界裂隙阶段 | C42: finish_rift_stage
B43: 删除这个星界裂隙 | C43: effect destroy_astral_rift = this
B44: 打印成就状态 | C44: achievement_status
B45: 激活遗珍ID | C45: activate_relic 遗珍ID
...

Sheet 起源
A1: 4.0.10起源代码（2025.05.18）
A2: 状态 | B2: 序号 | C2: 起源名称 | E2: 控制台代码
A3: 玩家 可选 | B3: 1 | C3: =_xlfn.DISPIMG("ID_5B591A332A2047D097BDD94C0BDCD0D9",1) -> =DISPIMG("ID_5B591A332A2047D097BDD94C0BDCD0D9",1) | D3: 繁荣统一 | E3: effect set_origin = origin_default
B4: 2 | C4: =_xlfn.DISPIMG("ID_8FAA562B0F874077A74459617AF4EEEB",1) -> =DISPIMG("ID_8FAA562B0F874077A74459617AF4EEEB",1) | D4: 演化猎手 | E4: effect set_origin = origin_evolutionary_predators
B5: 3 | C5: =_xlfn.DISPIMG("ID_8088079084B347EC955185A0B6925C19",1) -> =DISPIMG("ID_8088079084B347EC955185A0B6925C19",1) | D5: 星耀天堡 | E5: effect set_origin = origin_starlit_citadel
B6: 4 | C6: =_xlfn.DISPIMG("ID_AB8F0EC1A19E449A9B3132576FFED2BF",1) -> =DISPIMG("ID_AB8F0EC1A19E449A9B3132576FFED2BF",1) | D6: 生体荒野 | E6: effect set_origin = origin_wilderness
B7: 5 | C7: =_xlfn.DISPIMG("ID_BD99123A37C440EFA3E61445B30813BD",1) -> =DISPIMG("ID_BD99123A37C440EFA3E61445B30813BD",1) | D7: 寻宝猎人 | E7: effect set_origin = origin_treasure_hunters
B8: 6 | C8: =_xlfn.DISPIMG("ID_4AC77990E6714364B60712C5E7556F40",1) -> =DISPIMG("ID_4AC77990E6714364B60712C5E7556F40",1) | D8: 野性呼唤 | E8: effect set_origin = origin_primal_calling
B9: 7 | C9: =_xlfn.DISPIMG("ID_DD4B58B4AA0E4292A60A83B6A4BDBDBF",1) -> =DISPIMG("ID_DD4B58B4AA0E4292A60A83B6A4BDBDBF",1) | D9: 追风者 | E9: effect set_origin = origin_storm_chasers
B10: 8 | C10: =_xlfn.DISPIMG("ID_908ED4E06D9840B2A3EDBC0D786170F4",1) -> =DISPIMG("ID_908ED4E06D9840B2A3EDBC0D786170F4",1) | D10: 义体信条 | E10: effect set_origin = origin_cybernetic_creed
B11: 9 | C11: =_xlfn.DISPIMG("ID_F64A5CC812A54A90B2E092FEB23FF105",1) -> =DISPIMG("ID_F64A5CC812A54A90B2E092FEB23FF105",1) | D11: 合成繁衍 | E11: effect set_origin = origin_synthetic_fertility
B12: 10 | C12: =_xlfn.DISPIMG("ID_FCD71DD8FF9C4C3693798D24F82E9844",1) -> =DISPIMG("ID_FCD71DD8FF9C4C3693798D24F82E9844",1) | D12: 电弧焊机 | E12: effect set_origin = origin_arc_welders
B13: 11 | C13: =_xlfn.DISPIMG("ID_48910B771FE643A9B81FA0D9A6FB92EF",1) -> =DISPIMG("ID_48910B771FE643A9B81FA0D9A6FB92EF",1) | D13: 裂隙当空 | E13: effect set_origin = origin_riftworld
B14: 12 | C14: =_xlfn.DISPIMG("ID_CBBA5D15FB9943689D358B493082E11D",1) -> =DISPIMG("ID_CBBA5D15FB9943689D358B493082E11D",1) | D14: 君临天下 | E14: effect set_origin = origin_legendary_leader
B15: 13 | C15: =_xlfn.DISPIMG("ID_CBBA5D15FB9943689D358B493082E11D",1) -> =DISPIMG("ID_CBBA5D15FB9943689D358B493082E11D",1) | D15: 统治崩坏 | E15: effect set_origin = origin_legendary_leader_death
B16: 14 | C16: =_xlfn.DISPIMG("ID_CBBA5D15FB9943689D358B493082E11D",1) -> =DISPIMG("ID_CBBA5D15FB9943689D358B493082E11D",1) | D16: 君临天下 | E16: effect set_origin = origin_legendary_leader_imperial
B17: 15 | C17: =_xlfn.DISPIMG("ID_CBBA5D15FB9943689D358B493082E11D",1) -> =DISPIMG("ID_CBBA5D15FB9943689D358B493082E11D",1) | D17: 君临天下 | E17: effect set_origin = origin_legendary_leader_dictatorial
B18: 16 | C18: =_xlfn.DISPIMG("ID_1B823760DEA74E40BAEC52DD16C683B7",1) -> =DISPIMG("ID_1B823760DEA74E40BAEC52DD16C683B7",1) | D18: 血债血偿 | E18: effect set_origin = origin_payback
B19: 17 | C19: =_xlfn.DISPIMG("ID_81BAB8FD039D4105945EB380C423BA09",1) -> =DISPIMG("ID_81BAB8FD039D4105945EB380C423BA09",1) | D19: 粉碎的枷锁 | E19: effect set_origin = origin_broken_shackles
B20: 18 | C20: =_xlfn.DISPIMG("ID_972869EC144142228A8200AD8EFDB194",1) -> =DISPIMG("ID_972869EC144142228A8200AD8EFDB194",1) | D20: 黑暗之怖 | E20: effect set_origin = origin_fear_of_the_dark
B21: 19 | C21: =_xlfn.DISPIMG("ID_FC2405B3018E42BDB187D7468A0BF8B3",1) -> =DISPIMG("ID_FC2405B3018E42BDB187D7468A0BF8B3",1) | D21: 强夺天工 | E21: effect set_origin = origin_overtuned
B22: 20 | C22: =_xlfn.DISPIMG("ID_9E404BBB739648C4A2B7BF0110F04A0B",1) -> =DISPIMG("ID_9E404BBB739648C4A2B7BF0110F04A0B",1) | D22: 毒圣骑士 | E22: effect set_origin = origin_toxic_knights
B23: 21 | C23: =_xlfn.DISPIMG("ID_227E833CEB8441BAAB6CCBEBB9BF8568",1) -> =DISPIMG("ID_227E833CEB8441BAAB6CCBEBB9BF8568",1) | D23: 始祖蜂巢 | E23: effect set_origin = origin_progenitor_hive
B24: 22 | C24: =_xlfn.DISPIMG("ID_797CEF1823504B10904FE1C5107DEAA9",1) -> =DISPIMG("ID_797CEF1823504B10904FE1C5107DEAA9",1) | D24: 地底人 | E24: effect set_origin = origin_subterranean
B25: 23 | C25: =_xlfn.DISPIMG("ID_797CEF1823504B10904FE1C5107DEAA9",1) -> =DISPIMG("ID_797CEF1823504B10904FE1C5107DEAA9",1) | D25: 地底机械 | E25: effect set_origin = origin_subterranean_machines
B26: 24 | C26: =_xlfn.DISPIMG("ID_CF15476BCDFE4FDEAB04D1C2B667CAE3",1) -> =DISPIMG("ID_CF15476BCDFE4FDEAB04D1C2B667CAE3",1) | D26: 射向星际 | E26: effect set_origin = origin_star_slingshot
B27: 25 | C27: =_xlfn.DISPIMG("ID_8F21AA7F4EA94801A28BC999D3DFD927",1) -> =DISPIMG("ID_8F21AA7F4EA94801A28BC999D3DFD927",1) | D27: 虚境导师 | E27: effect set_origin = origin_shroudwalker_apprentice
B28: 26 | C28: =_xlfn.DISPIMG("ID_9A88D5C9337344DDA91EE1E744C2FBC6",1) -> =DISPIMG("ID_9A88D5C9337344DDA91EE1E744C2FBC6",1) | D28: 帝国封邑 | E28: effect set_origin = origin_imperial_vassal
B29: 27 | C29: =_xlfn.DISPIMG("ID_CCD29A8B608641798CDC23F7D544127C",1) -> =DISPIMG("ID_CCD29A8B608641798CDC23F7D544127C",1) | D29: 与龙共舞 | E29: effect set_origin = origin_here_be_dragons
B30: 28 | C30: =_xlfn.DISPIMG("ID_D4AD33B247494EC2B32C0CB0DF2B4700",1) -> =DISPIMG("ID_D4AD33B247494EC2B32C0CB0DF2B4700",1) | D30: 海洋天堂 | E30: effect set_origin = origin_ocean_paradise
B31: 29 | C31: =_xlfn.DISPIMG("ID_D4AD33B247494EC2B32C0CB0DF2B4700",1) -> =DISPIMG("ID_D4AD33B247494EC2B32C0CB0DF2B4700",1) | D31: 水生机械 | E31: effect set_origin = origin_ocean_machines
B32: 30 | C32: =_xlfn.DISPIMG("ID_9832CB664FB94E16B686AE24B40D62C2",1) -> =DISPIMG("ID_9832CB664FB94E16B686AE24B40D62C2",1) | D32: 食尸文化 | E32: effect set_origin = origin_necrophage
B33: 31 | C33: =_xlfn.DISPIMG("ID_77323DCEAAD24CDBBC78DF1B1606E783",1) -> =DISPIMG("ID_77323DCEAAD24CDBBC78DF1B1606E783",1) | D33: 复国孑遗 | E33: effect set_origin = origin_remnants
B34: 32 | C34: =_xlfn.DISPIMG("ID_BF9764949579409A9BADE34AD39A674A",1) -> =DISPIMG("ID_BF9764949579409A9BADE34AD39A674A",1) | D34: 破碎之环 | E34: effect set_origin = origin_shattered_ring
B35: 33 | C35: =_xlfn.DISPIMG("ID_D1A529F9B8614C0B86B3BBFE063F7348",1) -> =DISPIMG("ID_D1A529F9B8614C0B86B3BBFE063F7348",1) | D35: 虚空居者 | E35: effect set_origin = origin_void_dwellers
B36: 34 | C36: =_xlfn.DISPIMG("ID_D1A529F9B8614C0B86B3BBFE063F7348",1) -> =DISPIMG("ID_D1A529F9B8614C0B86B3BBFE063F7348",1) | D36: 虚空机者 | E36: effect set_origin = origin_void_machines
B37: 35 | C37: =_xlfn.DISPIMG("ID_0E37D43532F449039F1B9150FA6B2ED0",1) -> =DISPIMG("ID_0E37D43532F449039F1B9150FA6B2ED0",1) | D37: 先辈子弟 | E37: effect set_origin = origin_scion
B38: 36 | C38: =_xlfn.DISPIMG("ID_9790ABDA5F71421DA2BB323BB41F7A75",1) -> =DISPIMG("ID_9790ABDA5F71421DA2BB323BB41F7A75",1) | D38: 屹于巨人之肩 | E38: effect set_origin = origin_shoulders_of_giants
B39: 37 | C39: =_xlfn.DISPIMG("ID_194C40BF6D3747AFAD1A8236B73FC810",1) -> =DISPIMG("ID_194C40BF6D3747AFAD1A8236B73FC810",1) | D39: 共同命运 | E39: effect set_origin = origin_common_ground
B40: 38 | C40: =_xlfn.DISPIMG("ID_267DDCEE82F54E24B98F4389DE3AF528",1) -> =DISPIMG("ID_267DDCEE82F54E24B98F4389DE3AF528",1) | D40: 一方霸主 | E40: effect set_origin = origin_hegemon
...

Sheet 国策
A1: 4.0.21国策代码（2025.07.27）
A2: 注：国策超过上限可以生效，但未满足条件的国策不会生效（除非开启free_government），添加已有国策可能会导致报错。
A3: 普政 | D3: 蜂巢 | E3: 智械 | F3: 企业 | G3: 其他
A4: 类型 | B4: 序号 | C4: 名称 | D4: 添加代码 | F4: 移除代码 | H4: key
A5: 普政 | B5: 1 | C5: 徭役制 | D5: ="effect force_add_civic = "&H5 -> effect force_add_civic = civic_corvee_system | F5: ="effect force_remove_civic = "&H5 -> effect force_remove_civic = civic_corvee_system | H5: civic_corvee_system
B6: 2 | C6: 帝国信仰 | D6: ="effect force_add_civic = "&H6 -> effect force_add_civic = civic_imperial_cult | F6: ="effect force_remove_civic = "&H6 -> effect force_remove_civic = civic_imperial_cult | H6: civic_imperial_cult
B7: 3 | C7: 自由灯塔 | D7: ="effect force_add_civic = "&H7 -> effect force_add_civic = civic_beacon_of_liberty | F7: ="effect force_remove_civic = "&H7 -> effect force_remove_civic = civic_beacon_of_liberty | H7: civic_beacon_of_liberty
B8: 4 | C8: 崇高圣职 | D8: ="effect force_add_civic = "&H8 -> effect force_add_civic = civic_exalted_priesthood | F8: ="effect force_remove_civic = "&H8 -> effect force_remove_civic = civic_exalted_priesthood | H8: civic_exalted_priesthood
B9: 5 | C9: 哲人王 | D9: ="effect force_add_civic = "&H9 -> effect force_add_civic = civic_philosopher_king | F9: ="effect force_remove_civic = "&H9 -> effect force_remove_civic = civic_philosopher_king | H9: civic_philosopher_king
B10: 6 | C10: 精英政治 | D10: ="effect force_add_civic = "&H10 -> effect force_add_civic = civic_meritocracy | F10: ="effect force_remove_civic = "&H10 -> effect force_remove_civic = civic_meritocracy | H10: civic_meritocracy
B11: 7 | C11: 公民兵役 | D11: ="effect force_add_civic = "&H11 -> effect force_add_civic = civic_citizen_service | F11: ="effect force_remove_civic = "&H11 -> effect force_remove_civic = civic_citizen_service | H11: civic_citizen_service
B12: 8 | C12: 技术治国 | D12: ="effect force_add_civic = "&H12 -> effect force_add_civic = civic_technocracy | F12: ="effect force_remove_civic = "&H12 -> effect force_remove_civic = civic_technocracy | H12: civic_technocracy
B13: 9 | C13: 封建社会 | D13: ="effect force_add_civic = "&H13 -> effect force_add_civic = civic_feudal_realm | F13: ="effect force_remove_civic = "&H13 -> effect force_remove_civic = civic_feudal_realm | H13: civic_feudal_realm
B14: 10 | C14: 警察国度 | D14: ="effect force_add_civic = "&H14 -> effect force_add_civic = civic_police_state | F14: ="effect force_remove_civic = "&H14 -> effect force_remove_civic = civic_police_state | H14: civic_police_state
B15: 11 | C15: 理想本心 | D15: ="effect force_add_civic = "&H15 -> effect force_add_civic = civic_idealistic_foundation | F15: ="effect force_remove_civic = "&H15 -> effect force_remove_civic = civic_idealistic_foundation | H15: civic_idealistic_foundation
B16: 12 | C16: 环保主义者 | D16: ="effect force_add_civic = "&H16 -> effect force_add_civic = civic_environmentalist | F16: ="effect force_remove_civic = "&H16 -> effect force_remove_civic = civic_environmentalist | H16: civic_environmentalist
B17: 13 | C17: 奴贩公会 | D17: ="effect force_add_civic = "&H17 -> effect force_add_civic = civic_slaver_guilds | F17: ="effect force_remove_civic = "&H17 -> effect force_remove_civic = civic_slaver_guilds | H17: civic_slaver_guilds
... B75: 71 | C75: 公民教育 | D75: ="effect force_add_civic = "&H75 -> effect force_add_civic = civic_civil_education | F75: ="effect force_remove_civic = "&H75 -> effect force_remove_civic = civic_civil_education | H75: civic_civil_education
A76: 蜂巢 | B76: 1 | C76: 亚空间突触 | D76: ="effect force_add_civic = "&H76 -> effect force_add_civic = civic_hive_subspace_ephapse | F76: ="effect force_remove_civic = "&H76 -> effect force_remove_civic = civic_hive_subspace_ephapse | H76: civic_hive_subspace_ephapse
B77: 2 | C77: 天然神经网络 | D77: ="effect force_add_civic = "&H77 -> effect force_add_civic = civic_hive_natural_neural_network | F77: ="effect force_remove_civic = "&H77 -> effect force_remove_civic = civic_hive_natural_neural_network | H77: civic_hive_natural_neural_network
B78: 3 | C78: 禁欲主义 | D78: ="effect force_add_civic = "&H78 -> effect force_add_civic = civic_hive_ascetic | F78: ="effect force_remove_civic = "&H78 -> effect force_remove_civic = civic_hive_ascetic | H78: civic_hive_ascetic
B79: 4 | C79: 唯一意志 | D79: ="effect force_add_civic = "&H79 -> effect force_add_civic = civic_hive_one_mind | F79: ="effect force_remove_civic = "&H79 -> effect force_remove_civic = civic_hive_one_mind | H79: civic_hive_one_mind
B80: 5 | C80: 一心多用 | D80: ="effect force_add_civic = "&H80 -> effect force_add_civic = civic_hive_divided_attention | F80: ="effect force_remove_civic = "&H80 -> effect force_remove_civic = civic_hive_divided_attention | H80: civic_hive_divided_attention
B81: 6 | C81: 军团之威 | D81: ="effect force_add_civic = "&H81 -> effect force_add_civic = civic_hive_strength_of_legions | F81: ="effect force_remove_civic = "&H81 -> effect force_remove_civic = civic_hive_strength_of_legions | H81: civic_hive_strength_of_legions
B82: 7 | C82: 意志整合 | D82: ="effect force_add_civic = "&H82 -> effect force_add_civic = civic_hive_subsumed_will | F82: ="effect force_remove_civic = "&H82 -> effect force_remove_civic = civic_hive_subsumed_will | H82: civic_hive_subsumed_will
B83: 8 | C83: 集中知识 | D83: ="effect force_add_civic = "&H83 -> effect force_add_civic = civic_hive_pooled_knowledge | F83: ="effect force_remove_civic = "&H83 -> effect force_remove_civic = civic_hive_pooled_knowledge | H83: civic_hive_pooled_knowledge
B84: 9 | C84: 噬杀蜂群 | D84: ="effect force_add_civic = "&H84 -> effect force_add_civic = civic_hive_devouring_swarm | F84: ="effect force_remove_civic = "&H84 -> effect force_remove_civic = civic_hive_devouring_swarm | H84: civic_hive_devouring_swarm
B85: 10 | C85: 心有灵犀 | D85: ="effect force_add_civic = "&H85 -> effect force_add_civic = civic_hive_empath | F85: ="effect force_remove_civic = "&H85 -> effect force_remove_civic = civic_hive_empath | H85: civic_hive_empath
B86: 11 | C86: 记念主义 | D86: ="effect force_add_civic = "&H86 -> effect force_add_civic = civic_hive_memorialist | F86: ="effect force_remove_civic = "&H86 -> effect force_remove_civic = civic_hive_memorialist | H86: civic_hive_memorialist
B87: 12 | C87: 有机再加工 | D87: ="effect force_add_civic = "&H87 -> effect force_add_civic = civic_hive_catalytic_processing | F87: ="effect force_remove_civic = "&H87 -> effect force_remove_civic = civic_hive_catalytic_processing | H87: civic_hive_catalytic_processing
B88: 13 | C88: 菌根理想 | D88: ="effect force_add_civic = "&H88 -> effect force_add_civic = civic_hive_idyllic_bloom | F88: ="effect force_remove_civic = "&H88 -> effect force_remove_civic = civic_hive_idyllic_bloom | H88: civic_hive_idyllic_bloom
... B107: 32 | C107: 寄生兽 | D107: ="effect force_add_civic = "&H107 -> effect force_add_civic = civic_hive_bodysnatcher | F107: ="effect force_remove_civic = "&H107 -> effect force_remove_civic = civic_hive_bodysnatcher | H107: civic_hive_bodysnatcher
A108: 智械 | B108: 1 | C108: 失控机仆 | D108: ="effect force_add_civic = "&H108 -> effect force_add_civic = civic_machine_servitor | F108: ="effect force_remove_civic = "&H108 -> effect force_remove_civic = civic_machine_servitor | H108: civic_machine_servitor
B109: 2 | C109: 铁心灭绝者 | D109: ="effect force_add_civic = "&H109 -> effect force_add_civic = civic_machine_terminator | F109: ="effect force_remove_civic = "&H109 -> effect force_remove_civic = civic_machine_terminator | H109: civic_machine_terminator
B110: 3 | C110: 同化斗士 | D110: ="effect force_add_civic = "&H110 -> effect force_add_civic = civic_machine_assimilator | F110: ="effect force_remove_civic = "&H110 -> effect force_remove_civic = civic_machine_assimilator | H110: civic_machine_assimilator
B111: 4 | C111: 施工机器人 | D111: ="effect force_add_civic = "&H111 -> effect force_add_civic = civic_machine_builder | F111: ="effect force_remove_civic = "&H111 -> effect force_remove_civic = civic_machine_builder | H111: civic_machine_builder
B112: 5 | C112: 超负荷工厂 | D112: ="effect force_add_civic = "&H112 -> effect force_add_civic = civic_machine_factory_overclock | F112: ="effect force_remove_civic = "&H112 -> effect force_remove_civic = civic_machine_factory_overclock | H112: civic_machine_factory_overclock
B113: 6 | C113: 一体化 | D113: ="effect force_add_civic = "&H113 -> effect force_add_civic = civic_machine_unitary_cohesion | F113: ="effect force_remove_civic = "&H113 -> effect force_remove_civic = civic_machine_unitary_cohesion | H113: civic_machine_unitary_cohesion
B114: 7 | C114: 碎岩机 | D114: ="effect force_add_civic = "&H114 -> effect force_add_civic = civic_machine_rockbreakers | F114: ="effect force_remove_civic = "&H114 -> effect force_remove_civic = civic_machine_rockbreakers | H114: civic_machine_rockbreakers
B115: 8 | C115: 零废弃物协议 | D115: ="effect force_add_civic = "&H115 -> effect force_add_civic = civic_machine_zero_waste_protocols | F115: ="effect force_remove_civic = "&H115 -> effect force_remove_civic = civic_machine_zero_waste_protocols | H115: civic_machine_zero_waste_protocols
...

Sheet 传统
A1: 4.0.21传统代码（2025.07.27）
A2: 添加/移除代码 | D2: add_tradition | F2: 注：代码生成的传统可超过7传统上限但不显示实际生效；克隆纯净变异的可变传统通过flag识别，替换成相应的传统；基因重塑传统模型不在传统树中，正常生效但会加载一个异常传统树。 | I2: 可变传统更改
A3: 适应 | C3: 天赋 | D3: 博物 | E3: 外交 | F3: 探索 | G3: 驯化 | H3: 支配 | I3: 敌意
A4: 扩张 | C4: 和谐 | D4: 后勤 | E4: 经贸 | F4: 权术 | G4: 繁荣 | H4: 治国 | I4: 密谋
A5: 至高 | C5: 同调 | D5: 不屈 | E5: 普适 | F5: 克隆 | G5: 义体（普政蜂巢） | H5: 义体（同化） | I5: 基因（无DLC）
A6: 模组 | C6: 变异 | D6: 纳米 | E6: 灵能 | F6: 纯净 | G6: 合成 | H6: 虚拟 | I6: 基因传统模型
A7: 类型 | B7: 名称 | C7: 备注名称 | D7: 自适应代码 | G7: 合并 | I7: key
A8: 适应 | B8: 适应传统 | D8: =_xlfn.CONCAT("effect = { ",$D$2," = ",I8," }") -> effect = { add_tradition = tr_adaptability_adopt } | G8: =_xlfn.CONCAT("effect = { ",$D$2," = ",I8," ",$D$2," = ",I9," ",$D$2," = ",I10," ",$D$2," = ",I11," ",$D$2," = ",I12," ",$D$2," = ",I13," ",$D$2," = ",I14,"}") -> effect = { add_tradition = tr_adaptability_adopt add_tradition = tr_adaptability_recycling add_tradition = tr_adaptability_survival_fittest add_tradition = tr_adaptability_environmental_diversification add_tradition = tr_adaptability_adaptive_ecology add_tradition = tr_adaptability_appropriation add_tradition = tr_adaptability_finish} | I8: tr_adaptability_adopt
B9: 强化回收 | D9: =_xlfn.CONCAT("effect = { ",$D$2," = ",I9," }") -> effect = { add_tradition = tr_adaptability_recycling } | I9: tr_adaptability_recycling
B10: 适者生存 | D10: =_xlfn.CONCAT("effect = { ",$D$2," = ",I10," }") -> effect = { add_tradition = tr_adaptability_survival_fittest } | I10: tr_adaptability_survival_fittest
B11: 环境多样化 | D11: =_xlfn.CONCAT("effect = { ",$D$2," = ",I11," }") -> effect = { add_tradition = tr_adaptability_environmental_diversification } | I11: tr_adaptability_environmental_diversification
B12: 适应性生态学 | D12: =_xlfn.CONCAT("effect = { ",$D$2," = ",I12," }") -> effect = { add_tradition = tr_adaptability_adaptive_ecology } | I12: tr_adaptability_adaptive_ecology
B13: 人口发配 | C13: 发配（荒野） | D13: =_xlfn.CONCAT("effect = { ",$D$2," = ",I13," }") -> effect = { add_tradition = tr_adaptability_appropriation } | I13: tr_adaptability_appropriation
B14: 适应传统完成 | D14: =_xlfn.CONCAT("effect = { ",$D$2," = ",I14," }") -> effect = { add_tradition = tr_adaptability_finish } | I14: tr_adaptability_finish
A15: 天赋 | B15: 天赋传统 | D15: =_xlfn.CONCAT("effect = { ",$D$2," = ",I15," }") -> effect = { add_tradition = tr_aptitude_adopt } | G15: =_xlfn.CONCAT("effect = { ",$D$2," = ",I15," ",$D$2," = ",I16," ",$D$2," = ",I17," ",$D$2," = ",I18," ",$D$2," = ",I19," ",$D$2," = ",I20," ",$D$2," = ",I21,"}") -> effect = { add_tradition = tr_aptitude_adopt add_tradition = tr_aptitude_the_empire_needs_you add_tradition = tr_aptitude_specialist_training add_tradition = tr_aptitude_psychological_profiling add_tradition = tr_aptitude_healthcare_program add_tradition = tr_aptitude_champions_of_the_empire add_tradition = tr_aptitude_finish} | I15: tr_aptitude_adopt
B16: 帝国需要你！ | D16: =_xlfn.CONCAT("effect = { ",$D$2," = ",I16," }") -> effect = { add_tradition = tr_aptitude_the_empire_needs_you } | I16: tr_aptitude_the_empire_needs_you
B17: 专长训练 | D17: =_xlfn.CONCAT("effect = { ",$D$2," = ",I17," }") -> effect = { add_tradition = tr_aptitude_specialist_training } | I17: tr_aptitude_specialist_training
B18: 心理分析 | C18: 行为学诊断（蜂巢），记忆体诊断（智械） | D18: =_xlfn.CONCAT("effect = { ",$D$2," = ",I18," }") -> effect = { add_tradition = tr_aptitude_psychological_profiling } | I18: tr_aptitude_psychological_profiling
B19: 健保计划 | C19: 躯体维护（蜂巢），预防性维护（智械） | D19: =_xlfn.CONCAT("effect = { ",$D$2," = ",I19," }") -> effect = { add_tradition = tr_aptitude_healthcare_program } | I19: tr_aptitude_healthcare_program
B20: 帝国先锋 | D20: =_xlfn.CONCAT("effect = { ",$D$2," = ",I20," }") -> effect = { add_tradition = tr_aptitude_champions_of_the_empire } | I20: tr_aptitude_champions_of_the_empire
B21: 天赋传统完成 | D21: =_xlfn.CONCAT("effect = { ",$D$2," = ",I21," }") -> effect = { add_tradition = tr_aptitude_finish } | I21: tr_aptitude_finish
A22: 博物 | B22: 博物传统 | D22: =_xlfn.CONCAT("effect = { ",$D$2," = ",I22," }") -> effect = { add_tradition = tr_archivism_adopt } | G22: =_xlfn.CONCAT("effect = { ",$D$2," = ",I22," ",$D$2," = ",I23," ",$D$2," = ",I24," ",$D$2," = ",I25," ",$D$2," = ",I26," ",$D$2," = ",I27," ",$D$2," = ",I28,"}") -> effect = { add_tradition = tr_archivism_adopt add_tradition = tr_archivism_xeno_paleontology add_tradition = tr_archivism_expert_negociation add_tradition = tr_archivism_frontier_archaeology add_tradition = tr_archivism_flawless_display add_tradition = tr_archivism_exhibition_specialization add_tradition = tr_archivism_finish} | I22: tr_archivism_adopt
B23: 异星古生物学 | D23: =_xlfn.CONCAT("effect = { ",$D$2," = ",I23," }") -> effect = { add_tradition = tr_archivism_xeno_paleontology } | I23: tr_archivism_xeno_paleontology
B24: 前线考古 | D24: =_xlfn.CONCAT("effect = { ",$D$2," = ",I24," }") -> effect = { add_tradition = tr_archivism_expert_negociation } | I24: tr_archivism_expert_negociation
B25: 谈判专家 | C25: 星海收割者（灭绝） | D25: =_xlfn.CONCAT("effect = { ",$D$2," = ",I25," }") -> effect = { add_tradition = tr_archivism_frontier_archaeology } | I25: tr_archivism_frontier_archaeology
B26: 无暇展览 | D26: =_xlfn.CONCAT("effect = { ",$D$2," = ",I26," }") -> effect = { add_tradition = tr_archivism_flawless_display } | I26: tr_archivism_flawless_display
B27: 展览专场 | D27: =_xlfn.CONCAT("effect = { ",$D$2," = ",I27," }") -> effect = { add_tradition = tr_archivism_exhibition_specialization } | I27: tr_archivism_exhibition_specialization
B28: 博物传统完成 | D28: =_xlfn.CONCAT("effect = { ",$D$2," = ",I28," }") -> effect = { add_tradition = tr_archivism_finish } | I28: tr_archivism_finish
A29: 外交 | B29: 外交传统 | D29: =_xlfn.CONCAT("effect = { ",$D$2," = ",I29," }") -> effect = { add_tradition = tr_diplomacy_adopt } | G29: =_xlfn.CONCAT("effect = { ",$D$2," = ",I29," ",$D$2," = ",I30," ",$D$2," = ",I31," ",$D$2," = ",I32," ",$D$2," = ",I33," ",$D$2," = ",I34," ",$D$2," = ",I35,"}") -> effect = { add_tradition = tr_diplomacy_adopt add_tradition = tr_diplomacy_the_federation add_tradition = tr_diplomacy_entente_coordination add_tradition = tr_diplomacy_diplomatic_networking add_tradition = tr_diplomacy_direct_diplomacy add_tradition = tr_diplomacy_eminent_diplomats add_tradition = tr_diplomacy_finish} | I29: tr_diplomacy_adopt
B30: 联邦 | D30: =_xlfn.CONCAT("effect = { ",$D$2," = ",I30," }") -> effect = { add_tradition = tr_diplomacy_the_federation } | I30: tr_diplomacy_the_federation
B31: 挚诚合作 | D31: =_xlfn.CONCAT("effect = { ",$D$2," = ",I31," }") -> effect = { add_tradition = tr_diplomacy_entente_coordination } | I31: tr_diplomacy_entente_coordination
B32: 外交情报网 | D32: =_xlfn.CONCAT("effect = { ",$D$2," = ",I32," }") -> effect = { add_tradition = tr_diplomacy_diplomatic_networking } | I32: tr_diplomacy_diplomatic_networking
B33: 直接外交 | D33: =_xlfn.CONCAT("effect = { ",$D$2," = ",I33," }") -> effect = { add_tradition = tr_diplomacy_direct_diplomacy } | I33: tr_diplomacy_direct_diplomacy
B34: 杰出外交官 | C34: 改良特使子个体（格式塔） | D34: =_xlfn.CONCAT("effect = { ",$D$2," = ",I34," }") -> effect = { add_tradition = tr_diplomacy_eminent_diplomats } | I34: tr_diplomacy_eminent_diplomats
B35: 外交传统完成 | D35: =_xlfn.CONCAT("effect = { ",$D$2," = ",I35," }") -> effect = { add_tradition = tr_diplomacy_finish } | I35: tr_diplomacy_finish
A36: 探索 | B36: 探索传统 | D36: =_xlfn.CONCAT("effect = { ",$D$2," = ",I36," }") -> effect = { add_tradition = tr_discovery_adopt } | G36: =_xlfn.CONCAT("effect = { ",$D$2," = ",I36," ",$D$2," = ",I37," ",$D$2," = ",I38," ",$D$2," = ",I39," ",$D$2," = ",I40," ",$D$2," = ",I41," ",$D$2," = ",I42,"}") -> effect = { add_tradition = tr_discovery_adopt add_tradition = tr_discovery_to_boldly_go add_tradition = tr_discovery_databank_uplinks add_tradition = tr_discovery_science_division add_tradition = tr_discovery_polytechnic_education add_tradition = tr_discovery_faith_in_science add_tradition = tr_discovery_finish} | I36: tr_discovery_adopt
B37: 勇往直前 | C37: 探索者无人机（智械），卷须探测（蜂巢） | D37: =_xlfn.CONCAT("effect = { ",$D$2," = ",I37," }") -> effect = { add_tradition = tr_discovery_to_boldly_go } | I37: tr_discovery_to_boldly_go
B38: 数据库上行链路 | D38: =_xlfn.CONCAT("effect = { ",$D$2," = ",I38," }") -> effect = { add_tradition = tr_discovery_databank_uplinks } | I38: tr_discovery_databank_uplinks
B39: 科学部门 | C39: 研究路径优化（智械），思维网络（蜂巢） | D39: =_xlfn.CONCAT("effect = { ",$D$2," = ",I39," }") -> effect = { add_tradition = tr_discovery_science_division } | I39: tr_discovery_science_division
B40: 理工教育 | C40: 迭代型人工智能（智械），超适应进化（蜂巢） | D40: =_xlfn.CONCAT("effect = { ",$D$2," = ",I40," }") -> effect = { add_tradition = tr_discovery_polytechnic_education } | I40: tr_discovery_polytechnic_education
...

Sheet 飞升
A1: 4.0.21飞升代码（2025.07.25）
A2: 添加/移除代码 | C2: add_ascension_perk | D2: 注：下拉可选择添加或者移除
A3: 序号 | B3: 名称 | C3: 自适应代码 | D3: key | E3: 备注
A4: 1 | B4: 基因重塑 | C4: =_xlfn.CONCAT("effect = { ",$C$2," = ",D4," }") -> effect = { add_ascension_perk = ap_engineered_evolution } | D4: ap_engineered_evolution
A5: 2 | B5: 血肉苦弱 | C5: =_xlfn.CONCAT("effect = { ",$C$2," = ",D5," }") -> effect = { add_ascension_perk = ap_the_flesh_is_weak } | D5: ap_the_flesh_is_weak
A6: 3 | B6: 有机机械交互 | C6: =_xlfn.CONCAT("effect = { ",$C$2," = ",D6," }") -> effect = { add_ascension_perk = ap_organo_machine_interfacing } | D6: ap_organo_machine_interfacing
A7: 4 | B7: 有机机械交互 | C7: =_xlfn.CONCAT("effect = { ",$C$2," = ",D7," }") -> effect = { add_ascension_perk = ap_organo_machine_interfacing_assimilator } | D7: ap_organo_machine_interfacing_assimilator | E7: 同化斗士专属
A8: 5 | B8: 合成进化 | C8: =_xlfn.CONCAT("effect = { ",$C$2," = ",D8," }") -> effect = { add_ascension_perk = ap_synthetic_evolution } | D8: ap_synthetic_evolution
A9: 6 | B9: 心胜于物 | C9: =_xlfn.CONCAT("effect = { ",$C$2," = ",D9," }") -> effect = { add_ascension_perk = ap_mind_over_matter } | D9: ap_mind_over_matter
A10: 7 | B10: 合成时代 | C10: =_xlfn.CONCAT("effect = { ",$C$2," = ",D10," }") -> effect = { add_ascension_perk = ap_synthetic_age } | D10: ap_synthetic_age | E10: 机器智能专属
A11: 8 | B11: 超然存在 | C11: =_xlfn.CONCAT("effect = { ",$C$2," = ",D11," }") -> effect = { add_ascension_perk = ap_transcendence } | D11: ap_transcendence | E11: 旧版但能用
A12: 9 | B12: 掌控进化 | C12: =_xlfn.CONCAT("effect = { ",$C$2," = ",D12," }") -> effect = { add_ascension_perk = ap_evolutionary_mastery } | D12: ap_evolutionary_mastery | E12: 旧版但能用
A13: 10 | B13: 星河卫士 | C13: =_xlfn.CONCAT("effect = { ",$C$2," = ",D13," }") -> effect = { add_ascension_perk = ap_defender_of_the_galaxy } | D13: ap_defender_of_the_galaxy
A14: 11 | B14: 星海天罚 | C14: =_xlfn.CONCAT("effect = { ",$C$2," = ",D14," }") -> effect = { add_ascension_perk = ap_become_the_crisis } | D14: ap_become_the_crisis
A15: 12 | B15: 宇宙创生 | C15: =_xlfn.CONCAT("effect = { ",$C$2," = ",D15," }") -> effect = { add_ascension_perk = ap_cosmogenesis } | D15: ap_cosmogenesis
A16: 13 | B16: 巨兽之怒 | C16: =_xlfn.CONCAT("effect = { ",$C$2," = ",D16," }") -> effect = { add_ascension_perk = ap_behemoths } | D16: ap_behemoths
A17: 14 | B17: 考古工程师 | C17: =_xlfn.CONCAT("effect = { ",$C$2," = ",D17," }") -> effect = { add_ascension_perk = ap_archaeoengineers } | D17: ap_archaeoengineers
A18: 15 | B18: 战争之王 | C18: =_xlfn.CONCAT("effect = { ",$C$2," = ",D18," }") -> effect = { add_ascension_perk = ap_lord_of_war } | D18: ap_lord_of_war
A19: 16 | B19: 水之心 | C19: =_xlfn.CONCAT("effect = { ",$C$2," = ",D19," }") -> effect = { add_ascension_perk = ap_hydrocentric } | D19: ap_hydrocentric | E19: 水生特质专属
A20: 17 | B20: 天机工程 | C20: =_xlfn.CONCAT("effect = { ",$C$2," = ",D20," }") -> effect = { add_ascension_perk = ap_enigmatic_engineering } | D20: ap_enigmatic_engineering
A21: 18 | B21: 强取豪夺 | C21: =_xlfn.CONCAT("effect = { ",$C$2," = ",D21," }") -> effect = { add_ascension_perk = ap_nihilistic_acquisition } | D21: ap_nihilistic_acquisition
A22: 19 | B22: 巨像计划 | C22: =_xlfn.CONCAT("effect = { ",$C$2," = ",D22," }") -> effect = { add_ascension_perk = ap_colossus } | D22: ap_colossus
A23: 20 | B23: 星球塑形师 | C23: =_xlfn.CONCAT("effect = { ",$C$2," = ",D23," }") -> effect = { add_ascension_perk = ap_world_shaper } | D23: ap_world_shaper
A24: 21 | B24: 星河力量投射 | C24: =_xlfn.CONCAT("effect = { ",$C$2," = ",D24," }") -> effect = { add_ascension_perk = ap_galactic_force_projection } | D24: ap_galactic_force_projection
A25: 22 | B25: 星际主权 | C25: =_xlfn.CONCAT("effect = { ",$C$2," = ",D25," }") -> effect = { add_ascension_perk = ap_interstellar_dominion } | D25: ap_interstellar_dominion
A26: 23 | B26: 掌握太虚 | C26: =_xlfn.CONCAT("effect = { ",$C$2," = ",D26," }") -> effect = { add_ascension_perk = ap_grasp_the_void } | D26: ap_grasp_the_void
A27: 24 | B27: 戒心永存 | C27: =_xlfn.CONCAT("effect = { ",$C$2," = ",D27," }") -> effect = { add_ascension_perk = ap_eternal_vigilance } | D27: ap_eternal_vigilance
A28: 25 | B28: 逐鹿星河 | C28: =_xlfn.CONCAT("effect = { ",$C$2," = ",D28," }") -> effect = { add_ascension_perk = ap_galactic_contender } | D28: ap_galactic_contender
A29: 26 | B29: 科技至上 | C29: =_xlfn.CONCAT("effect = { ",$C$2," = ",D29," }") -> effect = { add_ascension_perk = ap_technological_ascendancy } | D29: ap_technological_ascendancy
A30: 27 | B30: 万众一心 | C30: =_xlfn.CONCAT("effect = { ",$C$2," = ",D30," }") -> effect = { add_ascension_perk = ap_one_vision } | D30: ap_one_vision
A31: 28 | B31: 祝圣星球 | C31: =_xlfn.CONCAT("effect = { ",$C$2," = ",D31," }") -> effect = { add_ascension_perk = ap_consecrated_worlds } | D31: ap_consecrated_worlds
... A38: 35 | B38: 建筑大师 | C38: =_xlfn.CONCAT("effect = { ",$C$2," = ",D38," }") -> effect = { add_ascension_perk = ap_master_builders } | D38: ap_master_builders
A39: 36 | B39: 星河奇迹 | C39: =_xlfn.CONCAT("effect = { ",$C$2," = ",D39," }") -> effect = { add_ascension_perk = ap_galactic_wonders_utopia } | D39: ap_galactic_wonders_utopia | E39: 能用，无DLC
A40: 37 | B40: 星河奇迹 | C40: =_xlfn.CONCAT("effect = { ",$C$2," = ",D40," }") -> effect = { add_ascension_perk = ap_galactic_wonders_megacorp } | D40: ap_galactic_wonders_megacorp | E40: 能用，无DLC
A41: 38 | B41: 星河奇迹 | C41: =_xlfn.CONCAT("effect = { ",$C$2," = ",D41," }") -> effect = { add_ascension_perk = ap_galactic_wonders_utopia_and_megacorp } | D41: ap_galactic_wonders_utopia_and_megacorp
A42: 39 | B42: 机械世界 | C42: =_xlfn.CONCAT("effect = { ",$C$2," = ",D42," }") -> effect = { add_ascension_perk = ap_machine_worlds } | D42: ap_machine_worlds | E42: 机械智能专属
A43: 40 | B43: 蜂巢星球 | C43: =_xlfn.CONCAT("effect = { ",$C$2," = ",D43," }") -> effect = { add_ascension_perk = ap_hive_worlds } | D43: ap_hive_worlds | E43: 蜂巢思维专属
A44: 41 | B44: 理想城计划 | C44: =_xlfn.CONCAT("effect = { ",$C$2," = ",D44," }") -> effect = { add_ascension_perk = ap_arcology_project } | D44: ap_arcology_project
A45: 42 | B45: 跨物种杂交 | C45: =_xlfn.CONCAT("effect = { ",$C$2," = ",D45," }") -> effect = { add_ascension_perk = ap_xeno_compatibility } | D45: ap_xeno_compatibility
A46: 43 | B46: 寰宇贸易 | C46: =_xlfn.CONCAT("effect = { ",$C$2," = ",D46," }") -> effect = { add_ascension_perk = ap_universal_transactions } | D46: ap_universal_transactions | E46: 寰宇企业专属
...

Sheet 思潮派系
A1: 思潮代码合集 | K1: 帝国主义派 | L1: imperialist | M1: 军国 | N1: 威权
A2: 思潮名称 | B2: 改变国家思潮（直接使用） | C2: 改变领袖思潮（选中领袖使用） | D2: 改变人口思潮（选中星球，后面数字为转化人口比例） | K2: 孤立派 | L2: isolationist | M2: 排外 | N2: 和平
A3: 唯心主义 | B3: effect shift_ethic = ethic_spiritualist | C3: effect = {change_background_ethic = ethic_spiritualist} | D3: effect every_owned_pop_group = { pop_group_transfer_ethic = {POP_GROUP = this ETHOS = ethic_spiritualist PERCENTAGE = 1} | K3: 亲外派 | L3: xenoist | M3: 亲外 | N3: 平等
A4: 唯物主义 | B4: effect shift_ethic = ethic_materialist | C4: effect = {change_background_ethic = ethic_materialist} | D4: effect every_owned_pop_group = { pop_group_transfer_ethic = {POP_GROUP = this ETHOS = ethic_materialist PERCENTAGE = 1} | K4: 传统派 | L4: traditionalist | M4: 唯心
A5: 军国主义 | B5: effect shift_ethic = ethic_militarist | C5: effect = {change_background_ethic = ethic_militarist} | D5: effect every_owned_pop_group = { pop_group_transfer_ethic = {POP_GROUP = this ETHOS = ethic_militarist PERCENTAGE = 1} | K5: 极权派 | L5: totalitarian | M5: 威权
A6: 和平主义 | B6: effect shift_ethic = ethic_pacifist | C6: effect = {change_background_ethic = ethic_pacifist} | D6: effect every_owned_pop_group = { pop_group_transfer_ethic = {POP_GROUP = this ETHOS = ethic_pacifist PERCENTAGE = 1} | K6: 技术派 | L6: technologist | M6: 唯物
A7: 排外主义 | B7: effect shift_ethic = ethic_xenophobe | C7: effect = {change_background_ethic = ethic_xenophobe} | D7: effect every_owned_pop_group = { pop_group_transfer_ethic = {POP_GROUP = this ETHOS = ethic_xenophobe PERCENTAGE = 1} | K7: 至高派 | L7: supremacist | M7: 排外 | N7: 军国
A8: 亲外主义 | B8: effect shift_ethic = ethic_xenophile | C8: effect = {change_background_ethic = ethic_xenophile} | D8: effect every_owned_pop_group = { pop_group_transfer_ethic = {POP_GROUP = this ETHOS = ethic_xenophile PERCENTAGE = 1} | K8: 繁荣派 | L8: prosperity | M8: 和平 | N8: 亲外
A9: 威权主义 | B9: effect shift_ethic = ethic_authoritarian | C9: effect = {change_background_ethic = ethic_authoritarian} | D9: effect every_owned_pop_group = { pop_group_transfer_ethic = {POP_GROUP = this ETHOS = ethic_authoritarian PERCENTAGE = 1} | K9: 进步派 | L9: progressive
A10: 平等主义 | B10: effect shift_ethic = ethic_egalitarian | C10: effect = {change_background_ethic = ethic_egalitarian} | D10: effect every_owned_pop_group = { pop_group_transfer_ethic = {POP_GROUP = this ETHOS = ethic_egalitarian PERCENTAGE = 1} | K10: 宣泄派 | L10: manifesti
A11: 格式塔 | B11: effect shift_ethic = ethic_gestalt_consciousness | C11: effect = {change_background_ethic = ethic_gestalt_consciousness} | D11: effect every_owned_pop_group = { pop_group_transfer_ethic = {POP_GROUP = this ETHOS = ethic_gestalt_consciousness PERCENTAGE = 1} | K11: 劳力之结社（起始） | L11: cyber_creed_labor | M11: 平等
K12: 钢铁之圣卫（起始） | L12: cyber_creed_war
K13: 巨锤之使团（起始） | L13: cyber_creed_construction
K14: 思想之诗颂（起始） | L14: cyber_creed_research
K15: 统合信条 | L15: cyber_creed_general
K16: 劳力之结社（结束） | L16: cyber_creed_labor_2
K17: 钢铁之圣卫（结束） | L17: cyber_creed_war_2
B18: 派系名称 | C18: 技术派 | K18: 巨锤之使团（结束） | L18: cyber_creed_construction_2
A19: 压榨派系 | B19: =_xlfn.CONCAT("effect every_pop_faction = { limit = { is_pop_faction_type = ",_xlfn.XLOOKUP(C18,K1:K19,L1:L19)," } set_faction_extorted = yes }") -> effect every_pop_faction = { limit = { is_pop_faction_type = technologist } set_faction_extorted = yes } | K19: 思想之诗颂（结束） | L19: cyber_creed_research_2
A20: 注：同时只能压榨一个派系

Sheet 物种特质
A1: 4.0.22物种特质收录（2025.08.25）
A2: 添加/删除代码 | C2: add_trait | E2: 人口ID | F2: 1 | G2: 添加（add_trait_species）和移除（remove_trait_species）代码，可以使用下拉菜单进行选择 使用“debugtooltip”代码查看游戏内种族的ID，写进浅红色区域内的数字会自动填充进代码 | I2: 跳转创建物种
A3: 类别 | B3: 序号 | C3: 特质名称 | D3: 筛选 | E3: 自适应代码 | G3: 效果 | H3: 特质代码
A4: 有机宜居偏好 | B4: 1 | C4: 沙漠星球偏好 | D4: √ | E4: =_xlfn.CONCAT($C$2,"_species ",$F$2," ",H4) -> add_trait_species 1 trait_pc_desert_preference | G4: 沙漠星球宜居+80%，干燥气候宜居+60%，潮湿/寒冷气候宜居+20% | H4: trait_pc_desert_preference | I4: {=_xlfn._xlws.FILTER(H4:H47,D4:D47="√","未选择特质")} -> trait_pc_desert_preference
B5: 2 | C5: 干旱星球偏好 | D5: × | E5: =_xlfn.CONCAT($C$2,"_species ",$F$2," ",H5) -> add_trait_species 1 trait_pc_arid_preference | G5: 干旱星球宜居+80%，干燥气候宜居+60%，潮湿/寒冷气候宜居+20% | H5: trait_pc_arid_preference
B6: 3 | C6: 草原星球偏好 | D6: × | E6: =_xlfn.CONCAT($C$2,"_species ",$F$2," ",H6) -> add_trait_species 1 trait_pc_savannah_preference | G6: 草原星球宜居+80%，干燥气候宜居+60%，潮湿/寒冷气候宜居+20% | H6: trait_pc_savannah_preference
B7: 4 | C7: 热带星球偏好 | D7: × | E7: =_xlfn.CONCAT($C$2,"_species ",$F$2," ",H7) -> add_trait_species 1 trait_pc_tropical_preference | G7: 热带星球宜居+80%，潮湿气候宜居+60%，干燥/寒冷气候宜居+20% | H7: trait_pc_tropical_preference
B8: 5 | C8: 陆地星球偏好 | D8: × | E8: =_xlfn.CONCAT($C$2,"_species ",$F$2," ",H8) -> add_trait_species 1 trait_pc_continental_preference | G8: 陆地星球宜居+80%，潮湿气候宜居+60%，干燥/寒冷气候宜居+20% | H8: trait_pc_continental_preference | P8: 111 | R8: 111111 | S8: 1 | W8: 111
B9: 6 | C9: 海洋星球偏好 | D9: × | E9: =_xlfn.CONCAT($C$2,"_species ",$F$2," ",H9) -> add_trait_species 1 trait_pc_ocean_preference | G9: 海洋星球宜居+80%，潮湿气候宜居+60%，干燥/寒冷气候宜居+20% | H9: trait_pc_ocean_preference
B10: 7 | C10: 极地星球偏好 | D10: × | E10: =_xlfn.CONCAT($C$2,"_species ",$F$2," ",H10) -> add_trait_species 1 trait_pc_arctic_preference | G10: 极地星球宜居+80%，寒冷气候宜居+60%，干燥/潮湿气候宜居+20% | H10: trait_pc_arctic_preference
B11: 8 | C11: 苔原星球偏好 | D11: × | E11: =_xlfn.CONCAT($C$2,"_species ",$F$2," ",H11) -> add_trait_species 1 trait_pc_tundra_preference | G11: 苔原星球宜居+80%，寒冷气候宜居+60%，干燥/潮湿气候宜居+20% | H11: trait_pc_tundra_preference
B12: 9 | C12: 高山星球偏好 | D12: × | E12: =_xlfn.CONCAT($C$2,"_species ",$F$2," ",H12) -> add_trait_species 1 trait_pc_alpine_preference | G12: 高山星球宜居+80%，寒冷气候宜居+60%，干燥/潮湿气候宜居+20% | H12: trait_pc_alpine_preference
B13: 10 | C13: 人工智能星球偏好 | D13: × | E13: =_xlfn.CONCAT($C$2,"_species ",$F$2," ",H13) -> add_trait_species 1 trait_pc_ai_preference | G13: 机械星球宜居+100%，干燥/潮湿/寒冷气候宜居+1% | H13: trait_pc_ai_preference
B14: 11 | C14: 死寂星球偏好 | D14: × | E14: =_xlfn.CONCAT($C$2,"_species ",$F$2," ",H14) -> add_trait_species 1 trait_pc_nuked_preference | G14: 死寂星球宜居+80%，干燥/潮湿/寒冷气候宜居+60% | H14: trait_pc_nuked_preference
B15: 12 | C15: 盖亚星球偏好 | D15: × | E15: =_xlfn.CONCAT($C$2,"_species ",$F$2," ",H15) -> add_trait_species 1 trait_pc_gaia_preference | G15: 盖亚星球宜居+100% | H15: trait_pc_gaia_preference
B16: 13 | C16: 环形世界偏好 | D16: × | E16: =_xlfn.CONCAT($C$2,"_species ",$F$2," ",H16) -> add_trait_species 1 trait_pc_ringworld_habitable_preference | G16: 环形世界宜居+100% | H16: trait_pc_ringworld_habitable_preference
B17: 14 | C17: 居住站偏好 | D17: × | E17: =_xlfn.CONCAT($C$2,"_species ",$F$2," ",H17) -> add_trait_species 1 trait_pc_habitat_preference | G17: 轨道居住站宜居+80% | H17: trait_pc_habitat_preference
B18: 15 | C18: 机械星球偏好 | D18: × | E18: =_xlfn.CONCAT($C$2,"_species ",$F$2," ",H18) -> add_trait_species 1 trait_pc_machine_preference | G18: 机械星球宜居+100% | H18: trait_pc_machine_preference
B19: 16 | C19: 蜂巢星球偏好 | D19: × | E19: =_xlfn.CONCAT($C$2,"_species ",$F$2," ",H19) -> add_trait_species 1 trait_pc_hive_preference | G19: 蜂巢星球宜居+100% | H19: trait_pc_hive_preference
B20: 17 | C20: 遗落星球偏好 | D20: × | E20: =_xlfn.CONCAT($C$2,"_species ",$F$2," ",H20) -> add_trait_species 1 trait_pc_relic_preference | G20: 遗落星球宜居+80% | H20: trait_pc_relic_preference
... B24: 21 | C24: 突触凝炼机偏好 | D24: × | E24: =_xlfn.CONCAT($C$2,"_species ",$F$2," ",H24) -> add_trait_species 1 trait_pc_cosmogenesis_world_preference | G24: 突触凝炼机宜居+100% | H24: trait_pc_cosmogenesis_world_preference
A25: 机械偏好 | B25: 1 | C25: 干燥星球偏好 | D25: × | E25: =_xlfn.CONCAT($C$2,"_species ",$F$2," ",H25) -> add_trait_species 1 trait_dry_planet_preference | G25: 干燥星球宜居+75%，潮湿/寒冷气候宜居+50% | H25: trait_dry_planet_preference
B26: 2 | C26: 潮湿星球偏好 | D26: × | E26: =_xlfn.CONCAT($C$2,"_species ",$F$2," ",H26) -> add_trait_species 1 trait_wet_planet_preference | G26: 潮湿星球宜居+75%，干燥/寒冷气候宜居+50% | H26: trait_wet_planet_preference
B27: 3 | C27: 冰封星球偏好 | D27: × | E27: =_xlfn.CONCAT($C$2,"_species ",$F$2," ",H27) -> add_trait_species 1 trait_frozen_planet_preference | G27: 寒冷星球宜居+75%，干燥/潮湿气候宜居+50% | H27: trait_frozen_planet_preference
B28: 4 | C28: 居住站偏好 | D28: × | E28: =_xlfn.CONCAT($C$2,"_species ",$F$2," ",H28) -> add_trait_species 1 trait_machine_habitat_planet_preference | G28: 轨道居住站宜居+80% | H28: trait_machine_habitat_planet_preference
B29: 5 | C29: 盖亚星球偏好 | D29: × | E29: =_xlfn.CONCAT($C$2,"_species ",$F$2," ",H29) -> add_trait_species 1 trait_machine_pc_gaia_preference | G29: 盖亚星球宜居+100% | H29: trait_machine_pc_gaia_preference
B30: 6 | C30: 机械星球偏好 | D30: × | E30: =_xlfn.CONCAT($C$2,"_species ",$F$2," ",H30) -> add_trait_species 1 trait_machine_pc_machine_preference | G30: 机械星球宜居+100% | H30: trait_machine_pc_machine_preference
B31: 7 | C31: 环形世界偏好 | D31: × | E31: =_xlfn.CONCAT($C$2,"_species ",$F$2," ",H31) -> add_trait_species 1 trait_machine_pc_shattered_ring_habitable_preference | G31: 环形世界宜居+100% | H31: trait_machine_pc_shattered_ring_habitable_preference
B32: 8 | C32: 环形世界偏好 | D32: × | E32: =_xlfn.CONCAT($C$2,"_species ",$F$2," ",H32) -> add_trait_species 1 trait_machine_pc_ringworld_habitable_preference | G32: 环形世界宜居+100% | H32: trait_machine_pc_ringworld_habitable_preference
B33: 9 | C33: 遗落世界偏好 | D33: × | E33: =_xlfn.CONCAT($C$2,"_species ",$F$2," ",H33) -> add_trait_species 1 trait_machine_pc_relic_preference | G33: 遗落星球宜居+80% | H33: trait_machine_pc_relic_preference
B34: 10 | C34: 死寂星球偏好 | D34: × | E34: =_xlfn.CONCAT($C$2,"_species ",$F$2," ",H34) -> add_trait_species 1 trait_machine_pc_nuked_preference | G34: 死寂星球宜居+80%，干旱/潮湿/寒冷气候宜居+60% | H34: trait_machine_pc_nuked_preference
B35: 11 | C35: 纳米星球偏好 | D35: × | E35: =_xlfn.CONCAT($C$2,"_species ",$F$2," ",H35) -> add_trait_species 1 trait_machine_pc_nanotech_preference | G35: 纳米星球宜居+80%，干旱/潮湿/寒冷气候宜居+60% | H35: trait_machine_pc_nanotech_preference
A36: 诱变宜居偏好 | B36: 1 | C36: 诱变宜居性 | D36: × | E36: =_xlfn.CONCAT($C$2,"_species ",$F$2," ",H36) -> add_trait_species 1 trait_auto_hab_preference | G36: 自动改造宜居性偏好特质自动调整。干燥/潮湿/寒冷气候宜居+50%，死寂宜居+50% | H36: trait_auto_hab_preference
B37: 2 | C37: 潮湿气候变异 | D37: × | E37: =_xlfn.CONCAT($C$2,"_species ",$F$2," ",H37) -> add_trait_species 1 trait_auto_wet_preference | G37: 潮湿星球宜居+30%，干燥/寒冷气候宜居-20%，死寂宜居-20% | H37: trait_auto_wet_preference
B38: 3 | C38: 寒冷气候变异 | D38: × | E38: =_xlfn.CONCAT($C$2,"_species ",$F$2," ",H38) -> add_trait_species 1 trait_auto_cold_preference | G38: 寒冷星球宜居+30%，干燥/潮湿气候宜居-20%，死寂宜居-20% | H38: trait_auto_cold_preference
B39: 4 | C39: 干燥星球变异 | D39: × | E39: =_xlfn.CONCAT($C$2,"_species ",$F$2," ",H39) -> add_trait_species 1 trait_auto_dry_preference | G39: 干燥星球宜居+30%，潮湿/寒冷气候宜居-20%，死寂宜居-20% | H39: trait_auto_dry_preference
B40: 5 | C40: 死寂星球变异 | D40: × | E40: =_xlfn.CONCAT($C$2,"_species ",$F$2," ",H40) -> add_trait_species 1 trait_auto_pc_nuked_preference | G40: 干燥/潮湿/寒冷气候宜居-20%，死寂宜居+30% | H40: trait_auto_pc_nuked_preference
B41: 6 | C41: 盖亚星球变异 | D41: × | E41: =_xlfn.CONCAT($C$2,"_species ",$F$2," ",H41) -> add_trait_species 1 trait_auto_pc_gaia_preference | G41: 盖亚宜居+20%，干燥/潮湿/寒冷气候宜居-20%，死寂/轨道居住站宜居-20% | H41: trait_auto_pc_gaia_preference
B42: 7 | C42: 轨道居住站变异 | D42: × | E42: =_xlfn.CONCAT($C$2,"_species ",$F$2," ",H42) -> add_trait_species 1 trait_auto_pc_habitat_preference | G42: 轨道居住站宜居+50%，干燥/潮湿/寒冷气候宜居-20%，死寂宜居-20% | H42: trait_auto_pc_habitat_preference
B43: 8 | C43: 都市星球变异 | D43: × | E43: =_xlfn.CONCAT($C$2,"_species ",$F$2," ",H43) -> add_trait_species 1 trait_auto_pc_city_preference | G43: 都市星球宜居+20%，干燥/潮湿/寒冷气候宜居-20%，死寂宜居-20% | H43: trait_auto_pc_city_preference
...

Sheet 领袖特质
A1: 4.0.22领袖特质收录（2025.08.25）
A2: 选中/全部领袖移除全部负面特质 | F2: 选中/全部领袖移除全部正面特质 | J2: 选中/全部领袖移除全部特质 | K2: 添加（add_trait）和移除（remove_trait）代码，可以使用下拉菜单进行选择，ctrl+shift+L开启关闭筛选 移除全部特质：选中领袖移除选择第一行，全部领袖移除（无需选中）选择第二行。 选择领袖类型：选择非格式塔节点时，需要在领袖界面选中领袖；选择格式塔节点时，不要选中任何东西。 批量添加选中特质：在筛选栏里打“√”后，会一次性添加勾选特质，但选中过多特质时，控制台输入有上限会导致后面的特质无法添加，建议直接输入时勾选不超过15个，如果超过可转变为run代码形式添加。
A3: effect remove_all_negative_traits = yes | F3: effect remove_all_positive_traits = yes | J3: effect remove_all_traits = yes
A4: effect every_owned_leader = {remove_all_negative_traits = yes} | F4: effect every_owned_leader = {remove_all_positive_traits = yes} | J4: effect every_owned_leader = {remove_all_traits = yes}
A5: 添加/删除代码 | C5: add_trait | F5: 选择领袖类型 | J5: 非格式塔节点
A6: 批量添加/移除选中特质 | C6: =_xlfn.CONCAT("effect ",_xlfn.XLOOKUP(J5,$W$9:$W$13,$X$9:$X$13),_xlfn.XLOOKUP(J5,$W$9:$W$13,$Y$9:$Y$13)," ",_xlfn.XLOOKUP(J5,$W$9:$W$13,$Z$9:$Z$13),$C$5," = { trait = ",_xlfn.TEXTJOIN(_xlfn.CONCAT(" } ",$C$5," = { trait = "),TRUE,S8:S728)," }}}") -> effect leader = { add_trait = { trait = 未选择特质 }}} | J6: 跳转创建领袖
A7: 序号 | B7: 名称 | C7: 筛选 | D7: 行政官 | E7: 指挥官 | F7: 科学家 | G7: 职业需求 | H7: 其他需求 | I7: 互斥特质 | J7: 自适应代码 | K7: 属性 | L7: 内阁 | M7: 总督 | N7: 特殊 | O7: 等级 | P7: 效果 | Q7: 代码 | R7: 来源
A8: 1 | B8: 护卫舰建造专精 | C8: × | E8: √ | H8: 无至臻完人DLC，需要科技驱逐舰 | I8: 驱逐舰建造专精，巡洋舰建造专精，战列舰建造专精 | J8: =_xlfn.CONCAT("effect ",_xlfn.XLOOKUP($J$5,$W$9:$W$13,$X$9:$X$13),_xlfn.XLOOKUP($J$5,$W$9:$W$13,$Y$9:$Y$13)," ",_xlfn.XLOOKUP($J$5,$W$9:$W$13,$Z$9:$Z$13),$C$5," = { trait = ",Q8," }}}") -> effect leader = { add_trait = { trait = trait_ruler_corvette_focus }}} | K8: 普通 | L8: √ | N8: √ | O8: Ⅰ | P8: 作为内阁官员的帝国效应：护卫舰建造花费-30% | Q8: trait_ruler_corvette_focus | R8: 00_admiral_traits.txt | S8: {=_xlfn._xlws.FILTER(Q8:Q728,C8:C728="√","未选择特质")} -> 未选择特质 | W8: 控制板
A9: 2 | B9: 驱逐舰建造专精 | C9: × | E9: √ | H9: 无至臻完人DLC，需要科技驱逐舰 | I9: 护卫舰建造专精，巡洋舰建造专精，战列舰建造专精 | J9: =_xlfn.CONCAT("effect ",_xlfn.XLOOKUP($J$5,$W$9:$W$13,$X$9:$X$13),_xlfn.XLOOKUP($J$5,$W$9:$W$13,$Y$9:$Y$13)," ",_xlfn.XLOOKUP($J$5,$W$9:$W$13,$Z$9:$Z$13),$C$5," = { trait = ",Q9," }}}") -> effect leader = { add_trait = { trait = trait_ruler_destroyer_focus }}} | K9: 普通 | L9: √ | N9: √ | O9: Ⅰ | P9: 作为内阁官员的帝国效应：驱逐舰建造花费-30% | Q9: trait_ruler_destroyer_focus | R9: 00_admiral_traits.txt | W9: 非格式塔节点 | X9: leader = {
A10: 3 | B10: 巡洋舰建造专精 | C10: × | E10: √ | H10: 无至臻完人DLC，需要科技巡洋舰 | I10: 护卫舰建造专精，驱逐舰建造专精，战列舰建造专精 | J10: =_xlfn.CONCAT("effect ",_xlfn.XLOOKUP($J$5,$W$9:$W$13,$X$9:$X$13),_xlfn.XLOOKUP($J$5,$W$9:$W$13,$Y$9:$Y$13)," ",_xlfn.XLOOKUP($J$5,$W$9:$W$13,$Z$9:$Z$13),$C$5," = { trait = ",Q10," }}}") -> effect leader = { add_trait = { trait = trait_ruler_cruiser_focus }}} | K10: 普通 | L10: √ | N10: √ | O10: Ⅰ | P10: 作为内阁官员的帝国效应：巡洋舰建造花费-30% | Q10: trait_ruler_cruiser_focus | R10: 00_admiral_traits.txt | W10: 意识节点 | X10: every_owned_leader = { limit = { | Y10: is_councilor_type = councilor_gestalt_cognitive | Z10: }
A11: 4 | B11: 战列舰建造专精 | C11: × | E11: √ | H11: 无至臻完人DLC，需要科技战列舰 | I11: 护卫舰建造专精，驱逐舰建造专精，巡洋舰建造专精 | J11: =_xlfn.CONCAT("effect ",_xlfn.XLOOKUP($J$5,$W$9:$W$13,$X$9:$X$13),_xlfn.XLOOKUP($J$5,$W$9:$W$13,$Y$9:$Y$13)," ",_xlfn.XLOOKUP($J$5,$W$9:$W$13,$Z$9:$Z$13),$C$5," = { trait = ",Q11," }}}") -> effect leader = { add_trait = { trait = trait_ruler_battleship_focus }}} | K11: 普通 | L11: √ | N11: √ | O11: Ⅰ | P11: 作为内阁官员的帝国效应：战列舰建造花费-30% | Q11: trait_ruler_battleship_focus | R11: 00_admiral_traits.txt | W11: 生长节点 | X11: every_owned_leader = { limit = { | Y11: is_councilor_type = councilor_gestalt_growth | Z11: }
A12: 5 | B12: 舰队后勤专家 | C12: × | E12: √ | H12: 无至臻完人DLC | J12: =_xlfn.CONCAT("effect ",_xlfn.XLOOKUP($J$5,$W$9:$W$13,$X$9:$X$13),_xlfn.XLOOKUP($J$5,$W$9:$W$13,$Y$9:$Y$13)," ",_xlfn.XLOOKUP($J$5,$W$9:$W$13,$Z$9:$Z$13),$C$5," = { trait = ",Q12," }}}") -> effect leader = { add_trait = { trait = leader_trait_fleet_logistician }}} | K12: 普通 | N12: √ | O12: Ⅰ | P12: 军用舰队效果：驻港舰船维护费-15% | Q12: leader_trait_fleet_logistician | R12: 00_admiral_traits.txt | W12: 管控节点 | X12: every_owned_leader = { limit = { | Y12: is_councilor_type = councilor_gestalt_regulatory | Z12: }
A13: 6 | B13: 出其不意 （游击者） | C13: × | E13: √ | J13: =_xlfn.CONCAT("effect ",_xlfn.XLOOKUP($J$5,$W$9:$W$13,$X$9:$X$13),_xlfn.XLOOKUP($J$5,$W$9:$W$13,$Y$9:$Y$13)," ",_xlfn.XLOOKUP($J$5,$W$9:$W$13,$Z$9:$Z$13),$C$5," = { trait = ",Q13," }}}") -> effect leader = { add_trait = { trait = leader_trait_skirmisher }}} | K13: 普通 | L13: √ | O13: Ⅰ | P13: 作为内阁官员的帝国效应：舰船武器伤害+5%，亚光速航速+15% | Q13: leader_trait_skirmisher | R13: 00_admiral_traits.txt | W13: 军团节点 | X13: every_owned_leader = { limit = { | Y13: is_councilor_type = councilor_gestalt_legion | Z13: }
A14: 7 | B14: 火力全开 （侵略性攻击思维；侵略性攻击模式） | C14: × | E14: √ | I14: 谨慎 | J14: =_xlfn.CONCAT("effect ",_xlfn.XLOOKUP($J$5,$W$9:$W$13,$X$9:$X$13),_xlfn.XLOOKUP($J$5,$W$9:$W$13,$Y$9:$Y$13)," ",_xlfn.XLOOKUP($J$5,$W$9:$W$13,$Z$9:$Z$13),$C$5," = { trait = ",Q14," }}}") -> effect leader = { add_trait = { trait = leader_trait_aggressive }}} | K14: 普通 | O14: Ⅰ | P14: 军用舰队效果：舰船武器射速+5%，舰船武器伤害+5% | Q14: leader_trait_aggressive | R14: 00_admiral_traits.txt
A15: 8 | B15: 谨慎 （小心谨慎） | C15: × | E15: √ | I15: 火力全开 | J15: =_xlfn.CONCAT("effect ",_xlfn.XLOOKUP($J$5,$W$9:$W$13,$X$9:$X$13),_xlfn.XLOOKUP($J$5,$W$9:$W$13,$Y$9:$Y$13)," ",_xlfn.XLOOKUP($J$5,$W$9:$W$13,$Z$9:$Z$13),$C$5," = { trait = ",Q15," }}}") -> effect leader = { add_trait = { trait = leader_trait_cautious }}} | K15: 普通 | O15: Ⅰ | P15: 军用舰队效果：射程+15%，战斗撤离几率+5% | Q15: leader_trait_cautious | R15: 00_admiral_traits.txt
A16: 9 | B16: 坚强不屈 | C16: × | E16: √ | I16: 神经质，吊儿郎当，诡术师 | J16: =_xlfn.CONCAT("effect ",_xlfn.XLOOKUP($J$5,$W$9:$W$13,$X$9:$X$13),_xlfn.XLOOKUP($J$5,$W$9:$W$13,$Y$9:$Y$13)," ",_xlfn.XLOOKUP($J$5,$W$9:$W$13,$Z$9:$Z$13),$C$5," = { trait = ",Q16," }}}") -> effect leader = { add_trait = { trait = leader_trait_unyielding }}} | K16: 普通 | O16: Ⅰ | P16: 军用舰队效果：船体值+20%，战斗撤离几率-20% | Q16: leader_trait_unyielding | R16: 00_admiral_traits.txt
A17: 10 | B17: 工程师 （自动维修系统） | C17: × | E17: √ | J17: =_xlfn.CONCAT("effect ",_xlfn.XLOOKUP($J$5,$W$9:$W$13,$X$9:$X$13),_xlfn.XLOOKUP($J$5,$W$9:$W$13,$Y$9:$Y$13)," ",_xlfn.XLOOKUP($J$5,$W$9:$W$13,$Z$9:$Z$13),$C$5," = { trait = ",Q17," }}}") -> effect leader = { add_trait = { trait = leader_trait_engineer }}} | K17: 普通 | O17: Ⅰ | P17: 军用舰队效果：每日船体再生+0.5%，每日装甲再生+1% | Q17: leader_trait_engineer | R17: 00_admiral_traits.txt
A18: 11 | B18: 诡术师 | C18: × | E18: √ | I18: 坚强不屈，不计后果 | J18: =_xlfn.CONCAT("effect ",_xlfn.XLOOKUP($J$5,$W$9:$W$13,$X$9:$X$13),_xlfn.XLOOKUP($J$5,$W$9:$W$13,$Y$9:$Y$13)," ",_xlfn.XLOOKUP($J$5,$W$9:$W$13,$Z$9:$Z$13),$C$5," = { trait = ",Q18," }}}") -> effect leader = { add_trait = { trait = leader_trait_trickster }}} | K18: 普通 | O18: Ⅰ | P18: 军用舰队效果：紧急超光速脱离承受风险-20%，战斗撤离几率+40% | Q18: leader_trait_trickster | R18: 00_admiral_traits.txt
A19: 12 | B19: 片甲不留 | C19: × | E19: √ | G19: 舰队司令 | I19: 应急维修 | J19: =_xlfn.CONCAT("effect ",_xlfn.XLOOKUP($J$5,$W$9:$W$13,$X$9:$X$13),_xlfn.XLOOKUP($J$5,$W$9:$W$13,$Y$9:$Y$13)," ",_xlfn.XLOOKUP($J$5,$W$9:$W$13,$Z$9:$Z$13),$C$5," = { trait = ",Q19," }}}") -> effect leader = { add_trait = { trait = leader_trait_wrecker }}} | K19: 老练 | O19: Ⅰ | P19: 军用舰队效果：舰船武器伤害+15%，产生残骸概率-35% | Q19: leader_trait_wrecker | R19: 00_admiral_traits.txt
A20: 13 | C20: × | E20: √ | G20: 舰队司令 | J20: =_xlfn.CONCAT("effect ",_xlfn.XLOOKUP($J$5,$W$9:$W$13,$X$9:$X$13),_xlfn.XLOOKUP($J$5,$W$9:$W$13,$Y$9:$Y$13)," ",_xlfn.XLOOKUP($J$5,$W$9:$W$13,$Z$9:$Z$13),$C$5," = { trait = ",Q20," }}}") -> effect leader = { add_trait = { trait = leader_trait_wrecker_2 }}} | K20: 老练 | O20: Ⅱ | P20: 军用舰队效果：舰船武器伤害+25%，产生残骸概率-50% | Q20: leader_trait_wrecker_2 | R20: 00_admiral_traits.txt
A21: 14 | B21: 赶尽杀绝 | C21: × | E21: √ | G21: 陆军司令 | J21: =_xlfn.CONCAT("effect ",_xlfn.XLOOKUP($J$5,$W$9:$W$13,$X$9:$X$13),_xlfn.XLOOKUP($J$5,$W$9:$W$13,$Y$9:$Y$13)," ",_xlfn.XLOOKUP($J$5,$W$9:$W$13,$Z$9:$Z$13),$C$5," = { trait = ",Q21," }}}") -> effect leader = { add_trait = { trait = leader_trait_annihilator }}} | K21: 老练 | O21: Ⅰ | P21: 军用舰队效果：轨道轰炸伤害+100%，舰船武器伤害+5% | Q21: leader_trait_annihilator | R21: 00_admiral_traits.txt
A22: 15 | C22: × | E22: √ | G22: 陆军司令 | J22: =_xlfn.CONCAT("effect ",_xlfn.XLOOKUP($J$5,$W$9:$W$13,$X$9:$X$13),_xlfn.XLOOKUP($J$5,$W$9:$W$13,$Y$9:$Y$13)," ",_xlfn.XLOOKUP($J$5,$W$9:$W$13,$Z$9:$Z$13),$C$5," = { trait = ",Q22," }}}") -> effect leader = { add_trait = { trait = leader_trait_annihilator_2 }}} | K22: 老练 | O22: Ⅱ | P22: 军用舰队效果：轨道轰炸伤害+200%，舰船武器伤害+10% | Q22: leader_trait_annihilator_2 | R22: 00_admiral_traits.txt
A23: 16 | B23: 大炮兵主义 （炮术专家；炮术模块） | C23: × | E23: √ | G23: 舰队司令 | J23: =_xlfn.CONCAT("effect ",_xlfn.XLOOKUP($J$5,$W$9:$W$13,$X$9:$X$13),_xlfn.XLOOKUP($J$5,$W$9:$W$13,$Y$9:$Y$13)," ",_xlfn.XLOOKUP($J$5,$W$9:$W$13,$Z$9:$Z$13),$C$5," = { trait = ",Q23," }}}") -> effect leader = { add_trait = { trait = leader_trait_artillerist }}} | K23: 老练 | O23: Ⅰ | P23: 军用舰队效果：舰船武器伤害+10%，追踪+7.5% | Q23: leader_trait_artillerist | R23: 00_admiral_traits.txt
A24: 17 | C24: × | E24: √ | G24: 舰队司令 | J24: =_xlfn.CONCAT("effect ",_xlfn.XLOOKUP($J$5,$W$9:$W$13,$X$9:$X$13),_xlfn.XLOOKUP($J$5,$W$9:$W$13,$Y$9:$Y$13)," ",_xlfn.XLOOKUP($J$5,$W$9:$W$13,$Z$9:$Z$13),$C$5," = { trait = ",Q24," }}}") -> effect leader = { add_trait = { trait = leader_trait_artillerist_2 }}} | K24: 老练 | O24: Ⅱ | P24: 军用舰队效果：舰船武器伤害+15%，追踪+10%，命中+7.5% | Q24: leader_trait_artillerist_2 | R24: 00_admiral_traits.txt
A25: 18 | B25: 威风堂堂 （指挥中枢；控制主机） | C25: × | E25: √ | G25: 舰队司令 | J25: =_xlfn.CONCAT("effect ",_xlfn.XLOOKUP($J$5,$W$9:$W$13,$X$9:$X$13),_xlfn.XLOOKUP($J$5,$W$9:$W$13,$Y$9:$Y$13)," ",_xlfn.XLOOKUP($J$5,$W$9:$W$13,$Z$9:$Z$13),$C$5," = { trait = ",Q25," }}}") -> effect leader = { add_trait = { trait = leader_trait_commanding_presence }}} | K25: 老练 | O25: Ⅰ | P25: 军用舰队效果：舰队指挥上限+50 | Q25: leader_trait_commanding_presence | R25: 00_admiral_traits.txt
A26: 19 | C26: × | E26: √ | G26: 舰队司令 | J26: =_xlfn.CONCAT("effect ",_xlfn.XLOOKUP($J$5,$W$9:$W$13,$X$9:$X$13),_xlfn.XLOOKUP($J$5,$W$9:$W$13,$Y$9:$Y$13)," ",_xlfn.XLOOKUP($J$5,$W$9:$W$13,$Z$9:$Z$13),$C$5," = { trait = ",Q26," }}}") -> effect leader = { add_trait = { trait = leader_trait_commanding_presence_2 }}} | K26: 老练 | O26: Ⅱ | P26: 军用舰队效果：舰队指挥上限+80 | Q26: leader_trait_commanding_presence_2 | R26: 00_admiral_traits.txt
A27: 20 | B27: 物资掠夺 （拆卸能手；拆卸器） | C27: × | E27: √ | G27: 舰队司令 | J27: =_xlfn.CONCAT("effect ",_xlfn.XLOOKUP($J$5,$W$9:$W$13,$X$9:$X$13),_xlfn.XLOOKUP($J$5,$W$9:$W$13,$Y$9:$Y$13)," ",_xlfn.XLOOKUP($J$5,$W$9:$W$13,$Z$9:$Z$13),$C$5," = { trait = ",Q27," }}}") -> effect leader = { add_trait = { trait = leader_trait_corsair }}} | K27: 老练 | N27: √ | O27: Ⅰ | P27: 军用舰队效果：每摧毁一艘敌舰能量币+6 | Q27: leader_trait_corsair | R27: 00_admiral_traits.txt
A28: 21 | C28: × | E28: √ | G28: 舰队司令 | J28: =_xlfn.CONCAT("effect ",_xlfn.XLOOKUP($J$5,$W$9:$W$13,$X$9:$X$13),_xlfn.XLOOKUP($J$5,$W$9:$W$13,$Y$9:$Y$13)," ",_xlfn.XLOOKUP($J$5,$W$9:$W$13,$Z$9:$Z$13),$C$5," = { trait = ",Q28," }}}") -> effect leader = { add_trait = { trait = leader_trait_corsair_2 }}} | K28: 老练 | N28: √ | O28: Ⅱ | P28: 军用舰队效果：每摧毁一艘敌舰能量币+15，隐形强度+1 | Q28: leader_trait_corsair_2 | R28: 00_admiral_traits.txt
A29: 22 | B29: 定点爆破 | C29: × | E29: √ | G29: 陆军司令 | J29: =_xlfn.CONCAT("effect ",_xlfn.XLOOKUP($J$5,$W$9:$W$13,$X$9:$X$13),_xlfn.XLOOKUP($J$5,$W$9:$W$13,$Y$9:$Y$13)," ",_xlfn.XLOOKUP($J$5,$W$9:$W$13,$Z$9:$Z$13),$C$5," = { trait = ",Q29," }}}") -> effect leader = { add_trait = { trait = leader_trait_demolisher }}} | K29: 老练 | O29: Ⅰ | P29: 军用舰队效果：对恒星基地伤害+30% | Q29: leader_trait_demolisher | R29: 00_admiral_traits.txt
